2019-07-27 15:15:38 httpbin_validator.py [line:79] ERROR: HTTPConnectionPool(host='221.2.155.35', port=8060): Max retries exceeded with url: http://httpbin.org/get (Caused by ProxyError('Cannot connect to proxy.', ConnectionResetError(10054, '远程主机强迫关闭了一个现有的连接。', None, 10054, None))))
Traceback (most recent call last):
  File "D:\myprofiles\python3.7.3\lib\site-packages\urllib3\connectionpool.py", line 603, in urlopen
    chunked=chunked)
  File "D:\myprofiles\python3.7.3\lib\site-packages\urllib3\connectionpool.py", line 387, in _make_request
    six.raise_from(e, None)
  File "<string>", line 2, in raise_from
  File "D:\myprofiles\python3.7.3\lib\site-packages\urllib3\connectionpool.py", line 383, in _make_request
    httplib_response = conn.getresponse()
  File "D:\myprofiles\python3.7.3\lib\http\client.py", line 1321, in getresponse
    response.begin()
  File "D:\myprofiles\python3.7.3\lib\http\client.py", line 296, in begin
    version, status, reason = self._read_status()
  File "D:\myprofiles\python3.7.3\lib\http\client.py", line 257, in _read_status
    line = str(self.fp.readline(_MAXLINE + 1), "iso-8859-1")
  File "D:\myprofiles\python3.7.3\lib\socket.py", line 589, in readinto
    return self._sock.recv_into(b)
ConnectionResetError: [WinError 10054] 远程主机强迫关闭了一个现有的连接。

During handling of the above exception, another exception occurred:

Traceback (most recent call last):
  File "D:\myprofiles\python3.7.3\lib\site-packages\requests\adapters.py", line 449, in send
    timeout=timeout
  File "D:\myprofiles\python3.7.3\lib\site-packages\urllib3\connectionpool.py", line 641, in urlopen
    _stacktrace=sys.exc_info()[2])
  File "D:\myprofiles\python3.7.3\lib\site-packages\urllib3\util\retry.py", line 399, in increment
    raise MaxRetryError(_pool, url, error or ResponseError(cause))
urllib3.exceptions.MaxRetryError: HTTPConnectionPool(host='221.2.155.35', port=8060): Max retries exceeded with url: http://httpbin.org/get (Caused by ProxyError('Cannot connect to proxy.', ConnectionResetError(10054, '远程主机强迫关闭了一个现有的连接。', None, 10054, None)))

During handling of the above exception, another exception occurred:

Traceback (most recent call last):
  File "E:/IProxyPool/core/proxy_validate/httpbin_validator.py", line 57, in __check_http_proxies
    response = requests.get(test_url, headers=get_request_headers(), proxies=proxies, timeout=TIME_OUT)
  File "D:\myprofiles\python3.7.3\lib\site-packages\requests\api.py", line 75, in get
    return request('get', url, params=params, **kwargs)
  File "D:\myprofiles\python3.7.3\lib\site-packages\requests\api.py", line 60, in request
    return session.request(method=method, url=url, **kwargs)
  File "D:\myprofiles\python3.7.3\lib\site-packages\requests\sessions.py", line 533, in request
    resp = self.send(prep, **send_kwargs)
  File "D:\myprofiles\python3.7.3\lib\site-packages\requests\sessions.py", line 646, in send
    r = adapter.send(request, **kwargs)
  File "D:\myprofiles\python3.7.3\lib\site-packages\requests\adapters.py", line 510, in send
    raise ProxyError(e, request=request)
requests.exceptions.ProxyError: HTTPConnectionPool(host='221.2.155.35', port=8060): Max retries exceeded with url: http://httpbin.org/get (Caused by ProxyError('Cannot connect to proxy.', ConnectionResetError(10054, '远程主机强迫关闭了一个现有的连接。', None, 10054, None)))
2019-07-27 15:15:38 httpbin_validator.py [line:79] ERROR: ('Connection aborted.', BadStatusLine('<html>\r\n')))
Traceback (most recent call last):
  File "D:\myprofiles\python3.7.3\lib\site-packages\urllib3\connectionpool.py", line 597, in urlopen
    self._prepare_proxy(conn)
  File "D:\myprofiles\python3.7.3\lib\site-packages\urllib3\connectionpool.py", line 807, in _prepare_proxy
    conn.connect()
  File "D:\myprofiles\python3.7.3\lib\site-packages\urllib3\connection.py", line 313, in connect
    self._tunnel()
  File "D:\myprofiles\python3.7.3\lib\http\client.py", line 906, in _tunnel
    (version, code, message) = response._read_status()
  File "D:\myprofiles\python3.7.3\lib\http\client.py", line 278, in _read_status
    raise BadStatusLine(line)
http.client.BadStatusLine: <html>


During handling of the above exception, another exception occurred:

Traceback (most recent call last):
  File "D:\myprofiles\python3.7.3\lib\site-packages\requests\adapters.py", line 449, in send
    timeout=timeout
  File "D:\myprofiles\python3.7.3\lib\site-packages\urllib3\connectionpool.py", line 641, in urlopen
    _stacktrace=sys.exc_info()[2])
  File "D:\myprofiles\python3.7.3\lib\site-packages\urllib3\util\retry.py", line 368, in increment
    raise six.reraise(type(error), error, _stacktrace)
  File "D:\myprofiles\python3.7.3\lib\site-packages\urllib3\packages\six.py", line 685, in reraise
    raise value.with_traceback(tb)
  File "D:\myprofiles\python3.7.3\lib\site-packages\urllib3\connectionpool.py", line 597, in urlopen
    self._prepare_proxy(conn)
  File "D:\myprofiles\python3.7.3\lib\site-packages\urllib3\connectionpool.py", line 807, in _prepare_proxy
    conn.connect()
  File "D:\myprofiles\python3.7.3\lib\site-packages\urllib3\connection.py", line 313, in connect
    self._tunnel()
  File "D:\myprofiles\python3.7.3\lib\http\client.py", line 906, in _tunnel
    (version, code, message) = response._read_status()
  File "D:\myprofiles\python3.7.3\lib\http\client.py", line 278, in _read_status
    raise BadStatusLine(line)
urllib3.exceptions.ProtocolError: ('Connection aborted.', BadStatusLine('<html>\r\n'))

During handling of the above exception, another exception occurred:

Traceback (most recent call last):
  File "E:/IProxyPool/core/proxy_validate/httpbin_validator.py", line 57, in __check_http_proxies
    response = requests.get(test_url, headers=get_request_headers(), proxies=proxies, timeout=TIME_OUT)
  File "D:\myprofiles\python3.7.3\lib\site-packages\requests\api.py", line 75, in get
    return request('get', url, params=params, **kwargs)
  File "D:\myprofiles\python3.7.3\lib\site-packages\requests\api.py", line 60, in request
    return session.request(method=method, url=url, **kwargs)
  File "D:\myprofiles\python3.7.3\lib\site-packages\requests\sessions.py", line 533, in request
    resp = self.send(prep, **send_kwargs)
  File "D:\myprofiles\python3.7.3\lib\site-packages\requests\sessions.py", line 646, in send
    r = adapter.send(request, **kwargs)
  File "D:\myprofiles\python3.7.3\lib\site-packages\requests\adapters.py", line 498, in send
    raise ConnectionError(err, request=request)
requests.exceptions.ConnectionError: ('Connection aborted.', BadStatusLine('<html>\r\n'))
